{
    "tests": [
        {
            "score": 0,
            "max_score": 30,
            "name": "test_sllist.py::test_1_push_back[load-tests]",
            "output": "\ngroup_name = 'load-tests'\n\n    def new_func(group_name):\n        group_stat = group_stats[group_name]\n        if not group_stat['passed']:\n>           assert group_stat['observed'] == group_stat['expected']\nE           assert 'Traceback (most recent call last):\\n  File \"/home/kris10d/.local/lib/python3.10/site-packages/byu_pytest_utils/dialog.py\", line 59, in dialog_exec\\n    executable = executable()\\n  File \"/mnt/c/Users/Riley/Desktop/CS235/cs235-assignments/Unit04-Mechanics-of-lists/homework4a-sllist/test_sllist.py\", line 9, in linked_list_bin\\n    return compile_cpp(\\'*.cpp\\', output_exec=\\'linked_list\\')\\n  File \"/home/kris10d/.local/lib/python3.10/site-packages/byu_pytest_utils/cpp_utils.py\", line 12, in compile_cpp\\n    raise Exception(f\\'\"{command}\" failed:\\\\n{proc.stdout}\\')\\nException: \"g++ -Wall -std=c++17 -o linked_list *.cpp\" failed:\\n/usr/bin/ld: /tmp/ccWJRvyz.o: in function `main\\':\\ntests.cpp:(.text+0x82c): multiple definition of `main\\'; /tmp/ccUWvJUN.o:mytest.cpp:(.text+0x0): first defined here\\ncollect2: error: ld returned 1 exit status\\n\\n' == ''\nE             + Traceback (most recent call last):\nE             +   File \"/home/kris10d/.local/lib/python3.10/site-packages/byu_pytest_utils/dialog.py\", line 59, in dialog_exec\nE             +     executable = executable()\nE             +   File \"/mnt/c/Users/Riley/Desktop/CS235/cs235-assignments/Unit04-Mechanics-of-lists/homework4a-sllist/test_sllist.py\", line 9, in linked_list_bin\nE             +     return compile_cpp('*.cpp', output_exec='linked_list')\nE             +   File \"/home/kris10d/.local/lib/python3.10/site-packages/byu_pytest_utils/cpp_utils.py\", line 12, in compile_cpp\nE             +     raise Exception(f'\"{command}\" failed:\\n{proc.stdout}')\nE             + Exception: \"g++ -Wall -std=c++17 -o linked_list *.cpp\" failed:\nE             + /usr/bin/ld: /tmp/ccWJRvyz.o: in function `main':\nE             + tests.cpp:(.text+0x82c): multiple definition of `main'; /tmp/ccUWvJUN.o:mytest.cpp:(.text+0x0): first defined here\nE             + collect2: error: ld returned 1 exit status\nE             +\n\n/home/kris10d/.local/lib/python3.10/site-packages/byu_pytest_utils/dialog.py:31: AssertionError",
            "visibility": "visible"
        },
        {
            "score": 0,
            "max_score": 30,
            "name": "test_sllist.py::test_2_pop_back[load-tests]",
            "output": "\ngroup_name = 'load-tests'\n\n    def new_func(group_name):\n        group_stat = group_stats[group_name]\n        if not group_stat['passed']:\n>           assert group_stat['observed'] == group_stat['expected']\nE           assert 'Traceback (most recent call last):\\n  File \"/home/kris10d/.local/lib/python3.10/site-packages/byu_pytest_utils/dialog.py\", line 59, in dialog_exec\\n    executable = executable()\\n  File \"/mnt/c/Users/Riley/Desktop/CS235/cs235-assignments/Unit04-Mechanics-of-lists/homework4a-sllist/test_sllist.py\", line 9, in linked_list_bin\\n    return compile_cpp(\\'*.cpp\\', output_exec=\\'linked_list\\')\\n  File \"/home/kris10d/.local/lib/python3.10/site-packages/byu_pytest_utils/cpp_utils.py\", line 12, in compile_cpp\\n    raise Exception(f\\'\"{command}\" failed:\\\\n{proc.stdout}\\')\\nException: \"g++ -Wall -std=c++17 -o linked_list *.cpp\" failed:\\n/usr/bin/ld: /tmp/ccapPGCu.o: in function `main\\':\\ntests.cpp:(.text+0x82c): multiple definition of `main\\'; /tmp/ccUqgixc.o:mytest.cpp:(.text+0x0): first defined here\\ncollect2: error: ld returned 1 exit status\\n\\n' == ''\nE             + Traceback (most recent call last):\nE             +   File \"/home/kris10d/.local/lib/python3.10/site-packages/byu_pytest_utils/dialog.py\", line 59, in dialog_exec\nE             +     executable = executable()\nE             +   File \"/mnt/c/Users/Riley/Desktop/CS235/cs235-assignments/Unit04-Mechanics-of-lists/homework4a-sllist/test_sllist.py\", line 9, in linked_list_bin\nE             +     return compile_cpp('*.cpp', output_exec='linked_list')\nE             +   File \"/home/kris10d/.local/lib/python3.10/site-packages/byu_pytest_utils/cpp_utils.py\", line 12, in compile_cpp\nE             +     raise Exception(f'\"{command}\" failed:\\n{proc.stdout}')\nE             + Exception: \"g++ -Wall -std=c++17 -o linked_list *.cpp\" failed:\nE             + /usr/bin/ld: /tmp/ccapPGCu.o: in function `main':\nE             + tests.cpp:(.text+0x82c): multiple definition of `main'; /tmp/ccUqgixc.o:mytest.cpp:(.text+0x0): first defined here\nE             + collect2: error: ld returned 1 exit status\nE             +\n\n/home/kris10d/.local/lib/python3.10/site-packages/byu_pytest_utils/dialog.py:31: AssertionError",
            "visibility": "visible"
        },
        {
            "score": 0,
            "max_score": 20,
            "name": "test_sllist.py::test_3_front[load-tests]",
            "output": "\ngroup_name = 'load-tests'\n\n    def new_func(group_name):\n        group_stat = group_stats[group_name]\n        if not group_stat['passed']:\n>           assert group_stat['observed'] == group_stat['expected']\nE           assert 'Traceback (most recent call last):\\n  File \"/home/kris10d/.local/lib/python3.10/site-packages/byu_pytest_utils/dialog.py\", line 59, in dialog_exec\\n    executable = executable()\\n  File \"/mnt/c/Users/Riley/Desktop/CS235/cs235-assignments/Unit04-Mechanics-of-lists/homework4a-sllist/test_sllist.py\", line 9, in linked_list_bin\\n    return compile_cpp(\\'*.cpp\\', output_exec=\\'linked_list\\')\\n  File \"/home/kris10d/.local/lib/python3.10/site-packages/byu_pytest_utils/cpp_utils.py\", line 12, in compile_cpp\\n    raise Exception(f\\'\"{command}\" failed:\\\\n{proc.stdout}\\')\\nException: \"g++ -Wall -std=c++17 -o linked_list *.cpp\" failed:\\n/usr/bin/ld: /tmp/ccGxWYuG.o: in function `main\\':\\ntests.cpp:(.text+0x82c): multiple definition of `main\\'; /tmp/ccmNd9RG.o:mytest.cpp:(.text+0x0): first defined here\\ncollect2: error: ld returned 1 exit status\\n\\n' == ''\nE             + Traceback (most recent call last):\nE             +   File \"/home/kris10d/.local/lib/python3.10/site-packages/byu_pytest_utils/dialog.py\", line 59, in dialog_exec\nE             +     executable = executable()\nE             +   File \"/mnt/c/Users/Riley/Desktop/CS235/cs235-assignments/Unit04-Mechanics-of-lists/homework4a-sllist/test_sllist.py\", line 9, in linked_list_bin\nE             +     return compile_cpp('*.cpp', output_exec='linked_list')\nE             +   File \"/home/kris10d/.local/lib/python3.10/site-packages/byu_pytest_utils/cpp_utils.py\", line 12, in compile_cpp\nE             +     raise Exception(f'\"{command}\" failed:\\n{proc.stdout}')\nE             + Exception: \"g++ -Wall -std=c++17 -o linked_list *.cpp\" failed:\nE             + /usr/bin/ld: /tmp/ccGxWYuG.o: in function `main':\nE             + tests.cpp:(.text+0x82c): multiple definition of `main'; /tmp/ccmNd9RG.o:mytest.cpp:(.text+0x0): first defined here\nE             + collect2: error: ld returned 1 exit status\nE             +\n\n/home/kris10d/.local/lib/python3.10/site-packages/byu_pytest_utils/dialog.py:31: AssertionError",
            "visibility": "visible"
        },
        {
            "score": 0,
            "max_score": 20,
            "name": "test_sllist.py::test_4_size_and_clear[load-tests]",
            "output": "\ngroup_name = 'load-tests'\n\n    def new_func(group_name):\n        group_stat = group_stats[group_name]\n        if not group_stat['passed']:\n>           assert group_stat['observed'] == group_stat['expected']\nE           assert 'Traceback (most recent call last):\\n  File \"/home/kris10d/.local/lib/python3.10/site-packages/byu_pytest_utils/dialog.py\", line 59, in dialog_exec\\n    executable = executable()\\n  File \"/mnt/c/Users/Riley/Desktop/CS235/cs235-assignments/Unit04-Mechanics-of-lists/homework4a-sllist/test_sllist.py\", line 9, in linked_list_bin\\n    return compile_cpp(\\'*.cpp\\', output_exec=\\'linked_list\\')\\n  File \"/home/kris10d/.local/lib/python3.10/site-packages/byu_pytest_utils/cpp_utils.py\", line 12, in compile_cpp\\n    raise Exception(f\\'\"{command}\" failed:\\\\n{proc.stdout}\\')\\nException: \"g++ -Wall -std=c++17 -o linked_list *.cpp\" failed:\\n/usr/bin/ld: /tmp/ccfgVeKq.o: in function `main\\':\\ntests.cpp:(.text+0x82c): multiple definition of `main\\'; /tmp/cc9mwyKO.o:mytest.cpp:(.text+0x0): first defined here\\ncollect2: error: ld returned 1 exit status\\n\\n' == ''\nE             + Traceback (most recent call last):\nE             +   File \"/home/kris10d/.local/lib/python3.10/site-packages/byu_pytest_utils/dialog.py\", line 59, in dialog_exec\nE             +     executable = executable()\nE             +   File \"/mnt/c/Users/Riley/Desktop/CS235/cs235-assignments/Unit04-Mechanics-of-lists/homework4a-sllist/test_sllist.py\", line 9, in linked_list_bin\nE             +     return compile_cpp('*.cpp', output_exec='linked_list')\nE             +   File \"/home/kris10d/.local/lib/python3.10/site-packages/byu_pytest_utils/cpp_utils.py\", line 12, in compile_cpp\nE             +     raise Exception(f'\"{command}\" failed:\\n{proc.stdout}')\nE             + Exception: \"g++ -Wall -std=c++17 -o linked_list *.cpp\" failed:\nE             + /usr/bin/ld: /tmp/ccfgVeKq.o: in function `main':\nE             + tests.cpp:(.text+0x82c): multiple definition of `main'; /tmp/cc9mwyKO.o:mytest.cpp:(.text+0x0): first defined here\nE             + collect2: error: ld returned 1 exit status\nE             +\n\n/home/kris10d/.local/lib/python3.10/site-packages/byu_pytest_utils/dialog.py:31: AssertionError",
            "visibility": "visible"
        }
    ]
}